<mujoco model="propeller_fluid_test">
  <option integrator="RK4" gravity="0 0 -9.8" timestep="0.004" density="1.225" viscosity="1.5e-4" wind="0 0 0" iterations="50"/>
  <compiler angle="degree" coordinate="global" inertiafromgeom="true" meshdir="/home/xiaoyu/BodyGen/assets/meshes"/>    
  <asset>
    <texture name="skybox" type="skybox" builtin="gradient" rgb1=".2 .3 .4" rgb2="0 0 0" width="800" height="800" mark="random" markrgb="1 1 1"/>
    <texture name="grid" type="2d" builtin="checker" rgb1=".2 .1 .2" rgb2=".3 .2 .3" width="300" height="300" mark="edge" markrgb=".3 .2 .3"/>
    <material name="grid" texture="grid" texrepeat="1 1" texuniform="true" reflectance=".2"/>
    <material name="self" rgba=".7 .5 .3 1"/>
    <mesh name="wing" file="wing.stl"/>
  </asset>
  <visual>
    <headlight ambient=".4 .4 .4" diffuse=".8 .8 .8" specular="0.1 0.1 0.1"/>
    <map znear=".001"/>
    <quality shadowsize="16384"/>
    <global offheight="1000" offwidth="1000"/>
  </visual>
  <default>
    <joint armature="1" limited="false"/>
    <geom conaffinity="0" condim="3" density="600" friction="1 0.5 0.5" margin="0.01" rgba=".7 .5 .3 1"/>
  </default>
  <worldbody>
    <light cutoff="100" diffuse="1 1 1" dir="0.3 0 -1.3" directional="true" exponent="1" pos="-30 0 130" specular=".1 .1 .1"/>
    <geom conaffinity="1" condim="3" name="floor" pos="0 0 0" rgba="1 1 1 1" size="400 400 .125" type="plane" material="grid"/>
    <body name="0" pos="0 0 0">
      <camera name="track" mode="trackcom" pos="0 -6 1" xyaxes="1 0 0 0 0.2 1"/>
      <joint armature="0" damping="0" limited="false" margin="0.01" name="root" pos="0 0 0" type="free"/>
      <geom name="0_0" fromto="0 0 0.2 2 0 0.2" size="0.06" type="capsule" fluidshape="ellipsoid"/>
      <geom name="0_1" fromto="1 0 0.2 1 2 0.2" size="0.06" type="capsule" fluidshape="ellipsoid"/>
      <geom name="0_2" fromto="0 2 0.2 2 2 0.2" size="0.06" type="capsule" fluidshape="ellipsoid"/>
      <body name="1" pos="0 0 0.2">
        <geom name="1" fromto="0 0 0.2 0 0 0.65" size="0.06" type="capsule" fluidshape="ellipsoid"/>
        <joint axis="0 0 1" name="1_joint" pos="0 0 0.5" type="hinge"/>
        <body name="11" pos="0 0.06 0.65">
          <geom name="11" type="mesh" mesh="wing" pos="0 0.06 0.65" euler="0 15 0" rgba=".7 .5 .3 1" fluidshape="ellipsoid"/>
          <joint axis="1 0 0" name="11_joint" pos="0 0.06 0.65" type="hinge" range="-40 40" limited="true"/>
          <body name="111" pos="0 0.36 0.65">
            <geom name="111" type="mesh" mesh="wing" pos="0 0.36 0.65" euler="0 15 0" rgba=".7 .5 .3 1" fluidshape="ellipsoid"/>
            <joint axis="1 0 0" name="111_joint" pos="0 0.36 0.65" type="hinge" range="-40 40" limited="true"/>
            <body name="1111" pos="0 0.66 0.65">
              <geom name="1111" type="mesh" mesh="wing" pos="0 0.66 0.65" euler="0 15 0" rgba=".7 .5 .3 1" fluidshape="ellipsoid"/>
              <joint axis="1 0 0" name="1111_joint" pos="0 0.66 0.65" type="hinge" range="-40 40" limited="true"/>
            </body>
          </body>
        </body>
        <body name="21" pos="0 -0.06 0.65">
          <geom name="21" type="mesh" mesh="wing" pos="0 -0.36 0.65" euler="0 -15 0" rgba=".7 .5 .3 1" fluidshape="ellipsoid"/>
          <joint axis="1 0 0" name="21_joint" pos="0 -0.06 0.65" type="hinge" range="-40 40" limited="true"/>
          <body name="121" pos="0 -0.36 0.65">
            <geom name="121" type="mesh" mesh="wing" pos="0 -0.66 0.65" euler="0 -15 0" rgba=".7 .5 .3 1" fluidshape="ellipsoid"/>
            <joint axis="1 0 0" name="121_joint" pos="0 -0.36 0.65" type="hinge" range="-40 40" limited="true"/>
            <body name="1121" pos="0 -0.66 0.65">
              <geom name="1121" type="mesh" mesh="wing" pos="0 -0.96 0.65" euler="0 -15 0" rgba=".7 .5 .3 1" fluidshape="ellipsoid"/>
              <joint axis="1 0 0" name="1121_joint" pos="0 -0.66 0.65" type="hinge" range="-40 40" limited="true"/>
            </body>
          </body>
        </body>
      </body>
      <body name="2" pos="2 0 0.2">
        <geom name="2" fromto="2 0 0.2 2 0 0.65" size="0.06" type="capsule" fluidshape="ellipsoid"/>
        <joint axis="0 0 1" name="2_joint" pos="2 0 0.5" type="hinge"/>
        <body name="12" pos="2 0.06 0.65">
          <geom name="12" type="mesh" mesh="wing" pos="2 0.06 0.65" euler="0 -15 0" rgba=".7 .5 .3 1" fluidshape="ellipsoid"/>
          <joint axis="1 0 0" name="12_joint" pos="2 0.06 0.65" type="hinge" range="-40 40" limited="true"/>
          <body name="112" pos="2 0.36 0.65">
            <geom name="112" type="mesh" mesh="wing" pos="2 0.36 0.65" euler="0 -15 0" rgba=".7 .5 .3 1" fluidshape="ellipsoid"/>
            <joint axis="1 0 0" name="112_joint" pos="2 0.36 0.65" type="hinge" range="-40 40" limited="true"/>
            <body name="1112" pos="2 0.66 0.65">
              <geom name="1112" type="mesh" mesh="wing" pos="2 0.66 0.65" euler="0 -15 0" rgba=".7 .5 .3 1" fluidshape="ellipsoid"/>
              <joint axis="1 0 0" name="1112_joint" pos="2 0.66 0.65" type="hinge" range="-40 40" limited="true"/>
            </body>
          </body>
        </body>
        <body name="22" pos="2 -0.06 0.65">
          <geom name="22" type="mesh" mesh="wing" pos="2 -0.36 0.65" euler="0 15 0" rgba=".7 .5 .3 1" fluidshape="ellipsoid"/>
          <joint axis="1 0 0" name="22_joint" pos="2 -0.06 0.65" type="hinge" range="-40 40" limited="true"/>
          <body name="122" pos="2 -0.36 0.65">
            <geom name="122" type="mesh" mesh="wing" pos="2 -0.66 0.65" euler="0 15 0" rgba=".7 .5 .3 1" fluidshape="ellipsoid"/>
            <joint axis="1 0 0" name="122_joint" pos="2 -0.36 0.65" type="hinge" range="-40 40" limited="true"/>
            <body name="1122" pos="2 -0.66 0.65">
              <geom name="1122" type="mesh" mesh="wing" pos="2 -0.96 0.65" euler="0 15 0" rgba=".7 .5 .3 1" fluidshape="ellipsoid"/>
              <joint axis="1 0 0" name="1122_joint" pos="2 -0.66 0.65" type="hinge" range="-40 40" limited="true"/>
            </body>
          </body>
        </body>
      </body>
      <body name="3" pos="0 2 0.2">
        <geom name="3" fromto="0 2 0.2 0 2 0.65" size="0.06" type="capsule" fluidshape="ellipsoid"/>
        <joint axis="0 0 1" name="3_joint" pos="0 2 0.5" type="hinge"/>
        <body name="13" pos="0 2.06 0.65">
          <geom name="13" type="mesh" mesh="wing" pos="0 2.06 0.65" euler="0 -15 0" rgba=".7 .5 .3 1" fluidshape="ellipsoid"/>
          <joint axis="1 0 0" name="13_joint" pos="0 2.06 0.65" type="hinge" range="-40 40" limited="true"/>
          <body name="113" pos="0 2.36 0.65">
            <geom name="113" type="mesh" mesh="wing" pos="0 2.36 0.65" euler="0 -15 0" rgba=".7 .5 .3 1" fluidshape="ellipsoid"/>
            <joint axis="1 0 0" name="113_joint" pos="0 2.36 0.65" type="hinge" range="-40 40" limited="true"/>
            <body name="1113" pos="0 2.66 0.65">
              <geom name="1113" type="mesh" mesh="wing" pos="0 2.66 0.65" euler="0 -15 0" rgba=".7 .5 .3 1" fluidshape="ellipsoid"/>
              <joint axis="1 0 0" name="1113_joint" pos="0 2.66 0.65" type="hinge" range="-40 40" limited="true"/>
            </body>
          </body>
        </body>
        <body name="23" pos="0 1.64 0.65">
          <geom name="23" type="mesh" mesh="wing" pos="0 1.64 0.65" euler="0 15 0" rgba=".7 .5 .3 1" fluidshape="ellipsoid"/>
          <joint axis="1 0 0" name="23_joint" pos="0 1.94 0.65" type="hinge" range="-40 40" limited="true"/>
          <body name="123" pos="0 1.34 0.65">
            <geom name="123" type="mesh" mesh="wing" pos="0 1.34 0.65" euler="0 15 0" rgba=".7 .5 .3 1" fluidshape="ellipsoid"/>
            <joint axis="1 0 0" name="123_joint" pos="0 1.64 0.65" type="hinge" range="-40 40" limited="true"/>
            <body name="1123" pos="0 1.04 0.65">
              <geom name="1123" type="mesh" mesh="wing" pos="0 1.04 0.65" euler="0 15 0" rgba=".7 .5 .3 1" fluidshape="ellipsoid"/>
              <joint axis="1 0 0" name="1123_joint" pos="0 1.34 0.65" type="hinge" range="-40 40" limited="true"/>
            </body>
          </body>
        </body>
      </body>
      <body name="4" pos="2 2 0.2">
        <geom name="4" fromto="2 2 0.2 2 2 0.65" size="0.06" type="capsule" fluidshape="ellipsoid"/>
        <joint axis="0 0 1" name="4_joint" pos="2 2 0.5" type="hinge"/>
        <body name="14" pos="2 2.06 0.65">
          <geom name="14" type="mesh" mesh="wing" pos="2 2.06 0.65" euler="0 15 0" rgba=".7 .5 .3 1" fluidshape="ellipsoid"/>
          <joint axis="1 0 0" name="14_joint" pos="2 2.06 0.65" type="hinge" range="-40 40" limited="true"/>
          <body name="114" pos="2 2.36 0.65">
            <geom name="114" type="mesh" mesh="wing" pos="2 2.36 0.65" euler="0 15 0" rgba=".7 .5 .3 1" fluidshape="ellipsoid"/>
            <joint axis="1 0 0" name="114_joint" pos="2 2.36 0.65" type="hinge" range="-40 40" limited="true"/>
            <body name="1114" pos="2 2.66 0.65">
              <geom name="1114" type="mesh" mesh="wing" pos="2 2.66 0.65" euler="0 15 0" rgba=".7 .5 .3 1" fluidshape="ellipsoid"/>
              <joint axis="1 0 0" name="1114_joint" pos="2 2.66 0.65" type="hinge" range="-40 40" limited="true"/>
            </body>
          </body>
        </body>
        <body name="24" pos="2 1.64 0.65">
          <geom name="24" type="mesh" mesh="wing" pos="2 1.64 0.65" euler="0 -15 0" rgba=".7 .5 .3 1" fluidshape="ellipsoid"/>
          <joint axis="1 0 0" name="24_joint" pos="2 1.94 0.65" type="hinge" range="-40 40" limited="true"/>
          <body name="124" pos="2 1.34 0.65">
            <geom name="124" type="mesh" mesh="wing" pos="2 1.34 0.65" euler="0 -15 0" rgba=".7 .5 .3 1" fluidshape="ellipsoid"/>
            <joint axis="1 0 0" name="124_joint" pos="2 1.64 0.65" type="hinge" range="-40 40" limited="true"/>
            <body name="1124" pos="2 1.04 0.65">
              <geom name="1124" type="mesh" mesh="wing" pos="2 1.04 0.65" euler="0 -15 0" rgba=".7 .5 .3 1" fluidshape="ellipsoid"/>
              <joint axis="1 0 0" name="1124_joint" pos="2 1.34 0.65" type="hinge" range="-40 40" limited="true"/>
            </body>
          </body>
        </body>
      </body>
    </body>
  </worldbody>
  <equality>
    <joint joint1="1_joint"/>
    <joint joint1="4_joint"/>
    <joint joint1="2_joint"/>
    <joint joint1="3_joint"/>
    <joint joint1="11_joint"/>
    <joint joint1="21_joint"/>
    <joint joint1="12_joint"/>
    <joint joint1="22_joint"/>
    <joint joint1="13_joint"/>
    <joint joint1="23_joint"/>
    <joint joint1="14_joint"/>
    <joint joint1="24_joint"/>
    <joint joint1="111_joint"/>
    <joint joint1="121_joint"/>
    <joint joint1="112_joint"/>
    <joint joint1="122_joint"/>
    <joint joint1="113_joint"/>
    <joint joint1="123_joint"/>
    <joint joint1="114_joint"/>
    <joint joint1="124_joint"/>
    <joint joint1="1111_joint"/>
    <joint joint1="1121_joint"/>
    <joint joint1="1112_joint"/>
    <joint joint1="1122_joint"/>
    <joint joint1="1113_joint"/>
    <joint joint1="1123_joint"/>
    <joint joint1="1114_joint"/>
    <joint joint1="1124_joint"/>
  </equality>
  <actuator>
    <motor ctrllimited="true" ctrlrange="-1.0 1.0" joint="1_joint" gear="300" name="1_joint"/>
    <motor ctrllimited="true" ctrlrange="-1.0 1.0" joint="4_joint" gear="300" name="4_joint"/>
    <motor ctrllimited="true" ctrlrange="-1.0 1.0" joint="2_joint" gear="300" name="2_joint"/>
    <motor ctrllimited="true" ctrlrange="-1.0 1.0" joint="3_joint" gear="300" name="3_joint"/>
    <motor ctrllimited="true" ctrlrange="-1.0 1.0" joint="11_joint" gear="300" name="11_joint"/>
    <motor ctrllimited="true" ctrlrange="-1.0 1.0" joint="21_joint" gear="300" name="21_joint"/>
    <motor ctrllimited="true" ctrlrange="-1.0 1.0" joint="12_joint" gear="300" name="12_joint"/>
    <motor ctrllimited="true" ctrlrange="-1.0 1.0" joint="22_joint" gear="300" name="22_joint"/>
    <motor ctrllimited="true" ctrlrange="-1.0 1.0" joint="13_joint" gear="300" name="13_joint"/>
    <motor ctrllimited="true" ctrlrange="-1.0 1.0" joint="23_joint" gear="300" name="23_joint"/>
    <motor ctrllimited="true" ctrlrange="-1.0 1.0" joint="14_joint" gear="300" name="14_joint"/>
    <motor ctrllimited="true" ctrlrange="-1.0 1.0" joint="24_joint" gear="300" name="24_joint"/>
    <motor ctrllimited="true" ctrlrange="-1.0 1.0" joint="111_joint" gear="300" name="111_joint"/>
    <motor ctrllimited="true" ctrlrange="-1.0 1.0" joint="121_joint" gear="300" name="121_joint"/>
    <motor ctrllimited="true" ctrlrange="-1.0 1.0" joint="112_joint" gear="300" name="112_joint"/>
    <motor ctrllimited="true" ctrlrange="-1.0 1.0" joint="122_joint" gear="300" name="122_joint"/>
    <motor ctrllimited="true" ctrlrange="-1.0 1.0" joint="113_joint" gear="300" name="113_joint"/>
    <motor ctrllimited="true" ctrlrange="-1.0 1.0" joint="123_joint" gear="300" name="123_joint"/>
    <motor ctrllimited="true" ctrlrange="-1.0 1.0" joint="114_joint" gear="300" name="114_joint"/> 
    <motor ctrllimited="true" ctrlrange="-1.0 1.0" joint="124_joint" gear="300" name="124_joint"/>
    <motor ctrllimited="true" ctrlrange="-1.0 1.0" joint="1111_joint" gear="300" name="1111_joint"/>
    <motor ctrllimited="true" ctrlrange="-1.0 1.0" joint="1121_joint" gear="300" name="1121_joint"/>
    <motor ctrllimited="true" ctrlrange="-1.0 1.0" joint="1112_joint" gear="300" name="1112_joint"/>
    <motor ctrllimited="true" ctrlrange="-1.0 1.0" joint="1122_joint" gear="300" name="1122_joint"/>
    <motor ctrllimited="true" ctrlrange="-1.0 1.0" joint="1113_joint" gear="300" name="1113_joint"/>
    <motor ctrllimited="true" ctrlrange="-1.0 1.0" joint="1123_joint" gear="300" name="1123_joint"/>
    <motor ctrllimited="true" ctrlrange="-1.0 1.0" joint="1114_joint" gear="300" name="1114_joint"/>
    <motor ctrllimited="true" ctrlrange="-1.0 1.0" joint="1124_joint" gear="300" name="1124_joint"/>
  </actuator>
</mujoco>