<mujoco model="swim_walk_car">
  <option integrator="RK4" gravity="0 0 -9.81" timestep="0.004" density="1.225" viscosity="1.5e-5" wind="0 0 0"/>
  <compiler angle="degree" coordinate="local" inertiafromgeom="true" eulerseq="XYZ" meshdir="/home/xiaoyu/BodyGen/assets/meshes/plane"/>    
  <asset>
    <texture name="skybox" type="skybox" builtin="gradient" rgb1=".2 .3 .4" rgb2="0 0 0" width="800" height="800" mark="random" markrgb="1 1 1"/>
    <texture name="grid" type="2d" builtin="checker" rgb1=".2 .1 .2" rgb2=".3 .2 .3" width="300" height="300" mark="edge" markrgb=".3 .2 .3"/>
    <material name="grid" texture="grid" texrepeat="1 1" texuniform="true" reflectance=".2"/>
    <texture name="grid_wheel" type="2d" builtin="checker" rgb1=".3 .2 .1" rgb2=".5 .3 .2" width="300" height="300" mark="edge" markrgb=".2 .3 .2"/>
    <material name="grid_wheel" texture="grid_wheel" texrepeat="3 3" texuniform="true" reflectance=".2"/>
    <mesh name="wing" file="wing.stl" scale="0.5 1 0.5"/>
    <mesh name="wheel" file="wheel.stl" scale="1 1 1"/>
    <mesh name="slope" file="slope.obj" scale="1 1 1"/>
  </asset>
  <visual>
    <headlight ambient=".4 .4 .4" diffuse=".8 .8 .8" specular="0.1 0.1 0.1"/>
    <map znear=".001"/>
    <quality shadowsize="16384"/>
    <global offheight="1000" offwidth="1000"/>
  </visual>
  <default>
    <joint armature="0.1" limited="false"/>
    <geom conaffinity="0" condim="3" density="1000" friction="1 0.5 0.5" margin="0.01" rgba=".7 .5 .3 1"  solref="0.005 1.5"/>
    <equality solref="0.01 1.3"/>
  </default>
  <worldbody>
    <light cutoff="100" diffuse="1 1 1" dir="0.3 0 -1.3" directional="true" exponent="1" pos="-30 0 130" specular=".1 .1 .1"/>
    <geom conaffinity="1" condim="3" name="floor" pos="0 0 0" rgba="1 1 1 1" size="400 400 .125" type="plane" material="grid"/>
    <body name="0" pos="0 0 0.5">
      <camera name="track" mode="trackcom" pos="0.4 -4 0.4" xyaxes="1 0 0 0 0.2 1"/>
      <joint armature="0" damping="0" limited="false" margin="0.01" name="root" pos="0 0 0" type="free"/>
      <geom name="00" fromto="0 0 0 1 0 0" size="0.025" type="capsule" fluidshape="ellipsoid"/>
      <geom name="01" fromto="0 -0.4 0 0 0.4 0" size="0.025" type="capsule" fluidshape="ellipsoid"/>
      <geom name="02" fromto="1 -0.4 0 1 0.4 0" size="0.025" type="capsule" fluidshape="ellipsoid"/>
      <body name="1" pos="1 0.4 0">
        <joint axis="-1 0 0" name="1_x_joint" pos="0 0 0" limited="true" range="-90 90" type="hinge"/>
        <joint axis="0 0 -1" name="1_z_joint" pos="0 0 0" limited="true" range="-90 90" type="hinge"/>
        <geom name="10" fromto="0 0 0 0 0.2 0" size="0.025" type="capsule" fluidshape="ellipsoid"/>
        <body name="11_out" pos="0 0.2 0">
          <joint axis="0 1 0" name="11_joint_out" pos="0 0 0" type="hinge"/>
          <geom name="110" pos="0 0 0" type="mesh" mesh="wheel" material="grid_wheel" rgba="1 1 1 1" fluidshape="ellipsoid"/>
        </body>
        <body name="11_in" pos="0 0.2 0">
          <joint axis="0 1 0" name="11_joint_in" pos="0 0 0" type="hinge"/>
          <geom name="111" type="mesh" mesh="wing" pos="0 -0.025 0.025" euler="90 0 15" fluidshape="ellipsoid"/>
          <geom name="112" type="mesh" mesh="wing" pos="-0.025 -0.025 0" euler="0 -75 90" fluidshape="ellipsoid"/>
          <geom name="113" type="mesh" mesh="wing" pos="0.025 -0.025 0" euler="0 -75 -90" fluidshape="ellipsoid"/>
          <geom name="114" type="mesh" mesh="wing" pos="0 -0.025 -0.025" euler="-90 0 -15" fluidshape="ellipsoid"/>
        </body>
      </body>
      <body name="2" pos="0 0.4 0">
        <joint axis="-1 0 0" name="2_x_joint" pos="0 0 0" limited="true" range="-90 90" type="hinge"/>
        <joint axis="0 0 -1" name="2_z_joint" pos="0 0 0" limited="true" range="-90 90" type="hinge"/>
        <geom name="20" fromto="0 0 0 0 0.2 0" size="0.025" type="capsule" fluidshape="ellipsoid"/>
        <body name="21_out" pos="0 0.2 0">
          <joint axis="0 1 0" name="21_joint_out" pos="0 0 0" type="hinge"/>
          <geom name="210" pos="0 0 0" type="mesh" mesh="wheel" material="grid_wheel" rgba="1 1 1 1" fluidshape="ellipsoid"/>
        </body>
        <body name="21_in" pos="0 0.2 0">
          <joint axis="0 1 0" name="21_joint_in" pos="0 0 0" type="hinge"/>
          <geom name="211" type="mesh" mesh="wing" pos="0 -0.025 0.025" euler="90 0 15" fluidshape="ellipsoid"/>
          <geom name="212" type="mesh" mesh="wing" pos="-0.025 -0.025 0" euler="0 -75 90" fluidshape="ellipsoid"/>
          <geom name="213" type="mesh" mesh="wing" pos="0.025 -0.025 0" euler="0 -75 -90" fluidshape="ellipsoid"/>
          <geom name="214" type="mesh" mesh="wing" pos="0 -0.025 -0.025" euler="-90 0 -15" fluidshape="ellipsoid"/>
        </body>
      </body>
      <body name="3" pos="1 -0.4 0">
        <joint axis="1 0 0" name="3_x_joint" pos="0 0 0" limited="true" range="-90 90" type="hinge"/>
        <joint axis="0 0 1" name="3_z_joint" pos="0 0 0" limited="true" range="-90 90" type="hinge"/>
        <geom name="30" fromto="0 0 0 0 -0.2 0" size="0.025" type="capsule" fluidshape="ellipsoid"/>
        <body name="31_out" pos="0 -0.2 0">
          <joint axis="0 1 0" name="31_joint_out" pos="0 0 0" type="hinge"/>
          <geom name="310" pos="0 0 0" type="mesh" mesh="wheel" material="grid_wheel" rgba="1 1 1 1" euler="0 0 180" fluidshape="ellipsoid"/>
        </body>
        <body name="31_in" pos="0 -0.2 0">
          <joint axis="0 1 0" name="31_joint_in" pos="0 0 0" type="hinge"/>
          <geom name="311" type="mesh" mesh="wing" pos="0 0.025 0.025" euler="90 0 -15" fluidshape="ellipsoid"/>
          <geom name="312" type="mesh" mesh="wing" pos="-0.025 0.025 0" euler="0 75 90" fluidshape="ellipsoid"/>
          <geom name="313" type="mesh" mesh="wing" pos="0.025 0.025 0" euler="0 75 -90" fluidshape="ellipsoid"/>
          <geom name="314" type="mesh" mesh="wing" pos="0 0.025 -0.025" euler="-90 0 15" fluidshape="ellipsoid"/>
        </body>
      </body>
      <body name="4" pos="0 -0.4 0">
        <joint axis="1 0 0" name="4_x_joint" pos="0 0 0" limited="true" range="-90 90" type="hinge"/>
        <joint axis="0 0 1" name="4_z_joint" pos="0 0 0" limited="true" range="-90 90" type="hinge"/>
        <geom name="40" fromto="0 0 0 0 -0.2 0" size="0.025" type="capsule" fluidshape="ellipsoid"/>
        <body name="41_out" pos="0 -0.2 0">
          <joint axis="0 1 0" name="41_joint_out" pos="0 0 0" type="hinge"/>
          <geom name="410" pos="0 0 0" type="mesh" mesh="wheel" material="grid_wheel" rgba="1 1 1 1" euler="0 0 180" fluidshape="ellipsoid"/>
        </body>
        <body name="41_in" pos="0 -0.2 0">
          <joint axis="0 1 0" name="41_joint_in" pos="0 0 0" type="hinge"/>
          <geom name="411" type="mesh" mesh="wing" pos="0 0.025 0.025" euler="90 0 -15" fluidshape="ellipsoid"/>
          <geom name="412" type="mesh" mesh="wing" pos="-0.025 0.025 0" euler="0 75 90" fluidshape="ellipsoid"/>
          <geom name="413" type="mesh" mesh="wing" pos="0.025 0.025 0" euler="0 75 -90" fluidshape="ellipsoid"/>
          <geom name="414" type="mesh" mesh="wing" pos="0 0.025 -0.025" euler="-90 0 15" fluidshape="ellipsoid"/>
        </body>
      </body>
    </body>
  </worldbody>
  <equality>
    <joint joint1="1_x_joint"/>
    <joint joint1="3_x_joint"/>
    <joint joint1="2_x_joint"/>
    <joint joint1="4_x_joint"/>
    <joint joint1="1_z_joint"/>
    <joint joint1="3_z_joint"/>
    <joint joint1="2_z_joint"/>
    <joint joint1="4_z_joint"/>
    <joint joint1="11_joint_out"/>
    <joint joint1="31_joint_out"/>
    <joint joint1="21_joint_out"/>
    <joint joint1="41_joint_out"/>
    <joint joint1="11_joint_in"/>
    <joint joint1="31_joint_in"/>
    <joint joint1="21_joint_in"/>
    <joint joint1="41_joint_in"/>
  </equality>
  <actuator>
    <motor name="11_wing_motor" ctrllimited="true" ctrlrange="-1.0 1.0" joint="11_joint_in" gear="300"/>
    <motor name="31_wing_motor" ctrllimited="true" ctrlrange="-1.0 1.0" joint="31_joint_in" gear="300"/>
    <motor name="21_wing_motor" ctrllimited="true" ctrlrange="-1.0 1.0" joint="21_joint_in" gear="300"/>
    <motor name="41_wing_motor" ctrllimited="true" ctrlrange="-1.0 1.0" joint="41_joint_in" gear="300"/>
    <motor name="lf_motor" ctrllimited="true" ctrlrange="-1.0 1.0" joint="11_joint_out" gear="100"/>
    <motor name="rf_motor" ctrllimited="true" ctrlrange="-1.0 1.0" joint="31_joint_out" gear="100"/>
    <motor name="lb_motor" ctrllimited="true" ctrlrange="-1.0 1.0" joint="21_joint_out" gear="100"/>
    <motor name="rb_motor" ctrllimited="true" ctrlrange="-1.0 1.0" joint="41_joint_out" gear="100"/>
  </actuator>
</mujoco>